Workbook

Sheet Raw Data
A2: INCOME STATEMENT
B4: 2023 | C4: 2024 | D4: 2025
A5: Revenues | B5: 51217 | C5: 51362 | D5: 46309
A6: Cost of Sales | B6: 28925 | C6: 28475 | D6: 26519
A7: Gross Profit | B7: 22292 | C7: 22887 | D7: 19790
A8: Demand Creation Expense | B8: 4060 | C8: 4285 | D8: 4689
A9: Operating Overhead Expense | B9: 12317 | C9: 12291 | D9: 11399
A10: Total SG&A | B10: 16377 | C10: 16576 | D10: 16088
A11: Interest Expense (Income), net | B11: -6 | C11: -161 | D11: -107
A12: Other (Income) Expense, net | B12: -280 | C12: -228 | D12: -76
A13: EBT | B13: 6201 | C13: 6700 | D13: 3885
A14: Income Tax Expense | B14: 1131 | C14: 1000 | D14: 666
A15: Net Income | B15: 5070 | C15: 5700 | D15: 3219
A16: Diluted EPS | B16: 3.23 | C16: 3.73 | D16: 2.16
A17: Diluted Shares Outstanding | B17: 1569.8 | C17: 1529.7 | D17: 1487.6
A19: CASH FLOW STATEMENT
B21: 2023 | C21: 2024 | D21: 2025
A22: Net Income | B22: 5070 | C22: 5700 | D22: 3219
A23: D&A | B23: 703 | C23: 796 | D23: 775
A24: Deferred Income Taxes | B24: -117 | C24: -497 | D24: -288
A25: Stock-Based Compensation | B25: 755 | C25: 804 | D25: 709
A26: Impairment and Other | B26: 156 | C26: 48 | D26: 33
A27: Net Foreign Currency Adjustments | B27: -213 | C27: -138 | D27: 37
A28: Change in AR | B28: 489 | C28: -329 | D28: -257
A29: Change in Inventories | B29: -133 | C29: 908 | D29: 120
A30: Change in Prepaid/Other | B30: -644 | C30: -260 | D30: -224
A31: Change in AP/Accrued Liabilities | B31: -225 | C31: 397 | D31: -426
A32: Cash from Operations | B32: 5841 | C32: 7429 | D32: 3598
A33: Purchases of Short-Term Investments | B33: -6059 | C33: -4767 | D33: -3234
... A38: Cash from Investing | B38: 564 | C38: 894 | D38: -275
A39: Increase in Notes Payable | B39: -4 | C39: — | D39: -1
A40: Repayment of Borrowings | B40: -500 | C40: — | D40: -1000
A41: Stock Option Proceeds | B41: 651 | C41: 667 | D41: 551
A42: Share Repurchases | B42: -5480 | C42: -4250 | D42: -2985
A43: Dividends | B43: -2012 | C43: -2169 | D43: -2300
A44: Other Financing | B44: -102 | C44: -136 | D44: -85
A45: Cash from Financing | B45: -7447 | C45: -5888 | D45: -5820
A46: FX Effect on Cash | B46: -91 | C46: -16 | D46: 1
A47: Net Change in Cash | B47: -1133 | C47: 2419 | D47: -2396
A48: Beginning Cash | B48: 8574 | C48: 7441 | D48: 9860
...

Sheet IS (real)
A2: Income Statement | B2: 2023A | C2: 2024A | D2: 2025A | E2: 2026E | F2: 2027E | G2: 2028E | H2: 2029E | I2: 2030E
A3: Revenues | B3: ='Raw Data'!B5 -> 51217 | C3: ='Raw Data'!C5 -> 51362 | D3: ='Raw Data'!D5 -> 46309 | E3: =D3*(1+Assumptions!E4) -> 46271.953 | F3: =E3*(1+Assumptions!F4) -> 46470.922 | G3: =F3*(1+Assumptions!G4) -> 48097.404 | H3: =G3*(1+Assumptions!H4) -> 50309.885 | I3: =H3*(1+Assumptions!I4) -> 52624.14
A4: Cost Of Sales | B4: ='Raw Data'!B6 -> 28925 | C4: ='Raw Data'!C6 -> 28475 | D4: ='Raw Data'!D6 -> 26519 | E4: =E3*(1-Assumptions!E6) -> 26094.379 | F4: =F3*(1-Assumptions!F6) -> 26206.585 | G4: =G3*(1-Assumptions!G6) -> 27123.815 | H4: =H3*(1-Assumptions!H6) -> 28371.511 | I4: =I3*(1-Assumptions!I6) -> 29676.6
A5: Gross Profit | B5: =B3-B4 -> 22292 | C5: =C3-C4 -> 22887 | D5: =D3-D4 -> 19790 | E5: =E3-E4 -> 20177.574 | F5: =F3-F4 -> 20264.337 | G5: =G3-G4 -> 20973.589 | H5: =H3-H4 -> 21938.374 | I5: =I3-I4 -> 22947.539
A6: Demand Creation Expense | B6: ='Raw Data'!B8 -> 4060 | C6: ='Raw Data'!C8 -> 4285 | D6: ='Raw Data'!D8 -> 4689 | E6: =E3*Assumptions!E10 -> 4071.2009 | F6: =F3*Assumptions!F10 -> 4088.707 | G6: =G3*Assumptions!G10 -> 4231.8118 | H6: =H3*Assumptions!H10 -> 4426.4751 | I6: =I3*Assumptions!I10 -> 4630.093
A7: Operating Overhead Expense | B7: ='Raw Data'!B9 -> 12317 | C7: ='Raw Data'!C9 -> 12291 | D7: ='Raw Data'!D9 -> 11399 | E7: =E3*Assumptions!E11 -> 11196.869 | F7: =F3*Assumptions!F11 -> 11245.016 | G7: =G3*Assumptions!G11 -> 11638.591 | H7: =H3*Assumptions!H11 -> 12173.967 | I7: =I3*Assumptions!I11 -> 12733.969
A8: Total SG&A | B8: =B6+B7 -> 16377 | C8: =C6+C7 -> 16576 | D8: =D6+D7 -> 16088 | E8: =E6+E7 -> 15268.07 | F8: =F6+F7 -> 15333.723 | G8: =G6+G7 -> 15870.403 | H8: =H6+H7 -> 16600.442 | I8: =I6+I7 -> 17364.062
A9: EBIT | B9: =B5-B8 -> 5915 | C9: =C5-C8 -> 6311 | D9: =D5-D8 -> 3702 | E9: =E5-E8 -> 4909.5036 | F9: =F5-F8 -> 4930.6145 | G9: =G5-G8 -> 5103.186 | H9: =H5-H8 -> 5337.9325 | I9: =I5-I8 -> 5583.4774
A10: Interest Expense (Income), net | B10: ='Raw Data'!B11 -> -6 | C10: ='Raw Data'!C11 -> -161 | D10: ='Raw Data'!D11 -> -107 | E10: =AVERAGE($B10:$D10) -> -91.333333 | F10: =AVERAGE($B10:$D10) -> -91.333333 | G10: =AVERAGE($B10:$D10) -> -91.333333 | H10: =AVERAGE($B10:$D10) -> -91.333333 | I10: =AVERAGE($B10:$D10) -> -91.333333
A11: Other (Income) Expense, net | B11: ='Raw Data'!B12 -> -280 | C11: ='Raw Data'!C12 -> -228 | D11: ='Raw Data'!D12 -> -76 | E11: =AVERAGE($B11:$D11) -> -194.66667 | F11: =AVERAGE($B11:$D11) -> -194.66667 | G11: =AVERAGE($B11:$D11) -> -194.66667 | H11: =AVERAGE($B11:$D11) -> -194.66667 | I11: =AVERAGE($B11:$D11) -> -194.66667
A12: EBT | B12: =B9-B10-B11 -> 6201 | C12: =C9-C10-C11 -> 6700 | D12: =D9-D10-D11 -> 3885 | E12: =E9-E10-E11 -> 5195.5036 | F12: =F9-F10-F11 -> 5216.6145 | G12: =G9-G10-G11 -> 5389.186 | H12: =H9-H10-H11 -> 5623.9325 | I12: =I9-I10-I11 -> 5869.4774
A13: Income Tax Expense | B13: ='Raw Data'!B14 -> 1131 | C13: ='Raw Data'!C14 -> 1000 | D13: ='Raw Data'!D14 -> 666 | E13: =E12*Assumptions!E12 -> 871.23788 | F13: =F12*Assumptions!F12 -> 874.77797 | G13: =G12*Assumptions!G12 -> 903.71662 | H13: =H12*Assumptions!H12 -> 943.08144 | I13: =I12*Assumptions!I12 -> 984.25705
A14: Net Income | B14: =B12-B13 -> 5070 | C14: =C12-C13 -> 5700 | D14: =D12-D13 -> 3219 | E14: =E12-E13 -> 4324.2657 | F14: =F12-F13 -> 4341.8365 | G14: =G12-G13 -> 4485.4693 | H14: =H12-H13 -> 4680.8511 | I14: =I12-I13 -> 4885.2204
A16: Memo: D&A | B16: ='Raw Data'!B23 -> 703 | C16: ='Raw Data'!C23 -> 796 | D16: ='Raw Data'!D23 -> 775 | E16: =E3*Assumptions!E14 -> 708.87333 | F16: =F3*Assumptions!F14 -> 711.92149 | G16: =G3*Assumptions!G14 -> 736.83874 | H16: =H3*Assumptions!H14 -> 770.73332 | I16: =I3*Assumptions!I14 -> 806.18705
A17: Memo: EBITDA | B17: =B16+B9 -> 6618 | C17: =C16+C9 -> 7107 | D17: =D16+D9 -> 4477 | E17: =E16+E9 -> 5618.3769 | F17: =F16+F9 -> 5642.5359 | G17: =G16+G9 -> 5840.0247 | H17: =H16+H9 -> 6108.6658 | I17: =I16+I9 -> 6389.6645
A18: Gross Margin % | B18: =B5/B3 -> 0.43524611 | C18: =C5/C3 -> 0.44560181 | D18: =D5/D3 -> 0.42734674 | E18: =E5/E3 -> 0.43606488 | F18: =F5/F3 -> 0.43606488 | G18: =G5/G3 -> 0.43606488 | H18: =H5/H3 -> 0.43606488 | I18: =I5/I3 -> 0.43606488
A19: EBIT Margin % | B19: =B9/B3 -> 0.115489 | C19: =C9/C3 -> 0.12287294 | D19: =D9/D3 -> 0.079941264 | E19: =E9/E3 -> 0.10610107 | F19: =F9/F3 -> 0.10610107 | G19: =G9/G3 -> 0.10610107 | H19: =H9/H3 -> 0.10610107 | I19: =I9/I3 -> 0.10610107
A20: EBITDA Margin % | B20: =B17/B3 -> 0.12921491 | C20: =C17/C3 -> 0.13837078 | D20: =D17/D3 -> 0.096676672 | E20: =E17/E3 -> 0.12142079 | F20: =F17/F3 -> 0.12142079 | G20: =G17/G3 -> 0.12142079 | H20: =H17/H3 -> 0.12142079 | I20: =I17/I3 -> 0.12142079
A21: Net Margin % | B21: =B14/B3 -> 0.09899057 | C21: =C14/C3 -> 0.11097699 | D21: =D14/D3 -> 0.069511326 | E21: =E14/E3 -> 0.093453279 | F21: =F14/F3 -> 0.093431253 | G21: =G14/G3 -> 0.093258033 | H21: =H14/H3 -> 0.093040385 | I21: =I14/I3 -> 0.092832308

Sheet BS (real)
A2: Balance Sheet | B2: 2024A | C2: 2025A | D2: 2026E | E2: 2027E | F2: 2028E | G2: 2029E | H2: 2030E
A3: ASSETS
A4: Cash & Equivalents | B4: ='CFS (real)'!C34 -> 9860 | C4: ='CFS (real)'!D34 -> 7464 | D4: ='CFS (real)'!E34 -> 8434.1169 | E4: ='CFS (real)'!F34 -> 8533.2295 | F4: ='CFS (real)'!G34 -> 8534.1698 | G4: ='CFS (real)'!H34 -> 8632.2315 | H4: ='CFS (real)'!I34 -> 8918.8482
A5: Short-Term Investments | B5: ='Raw Data'!B54 -> 1722 | C5: ='Raw Data'!C54 -> 1687 | D5: =D44 -> 3841.1667 | E5: =E44 -> 5919.8333 | F5: =F44 -> 7998.5 | G5: =G44 -> 10077.167 | H5: =H44 -> 12155.833
A6: Accounts Receivable | B6: ='Raw Data'!B55 -> 4427 | C6: ='Raw Data'!C55 -> 4717 | D6: ='IS (real)'!E3*Assumptions!E17 -> 4124.5539 | E6: ='IS (real)'!F3*Assumptions!F17 -> 4142.2895 | F6: ='IS (real)'!G3*Assumptions!G17 -> 4287.2696 | G6: ='IS (real)'!H3*Assumptions!H17 -> 4484.484 | H6: ='IS (real)'!I3*Assumptions!I17 -> 4690.7703
A7: Inventories | B7: ='Raw Data'!B56 -> 7519 | C7: ='Raw Data'!C56 -> 7489 | D7: ='IS (real)'!E3*Assumptions!E18 -> 6769.9316 | E7: ='IS (real)'!F3*Assumptions!F18 -> 6799.0423 | F7: ='IS (real)'!G3*Assumptions!G18 -> 7037.0088 | G7: ='IS (real)'!H3*Assumptions!H18 -> 7360.7112 | H7: ='IS (real)'!I3*Assumptions!I18 -> 7699.3039
A8: Prepaid Expenses & Other | B8: ='Raw Data'!B57 -> 1854 | C8: ='Raw Data'!C57 -> 2005 | D8: =AVERAGE($B$8:$C$8) -> 1929.5 | E8: =AVERAGE($B$8:$C$8) -> 1929.5 | F8: =AVERAGE($B$8:$C$8) -> 1929.5 | G8: =AVERAGE($B$8:$C$8) -> 1929.5 | H8: =AVERAGE($B$8:$C$8) -> 1929.5
A9: Total Current Assets | B9: =SUM(B4:B8) -> 25382 | C9: =SUM(C4:C8) -> 23362 | D9: =SUM(D4:D8) -> 25099.269 | E9: =SUM(E4:E8) -> 27323.895 | F9: =SUM(F4:F8) -> 29786.448 | G9: =SUM(G4:G8) -> 32484.093 | H9: =SUM(H4:H8) -> 35394.256
A10: PP&E, net | B10: ='Raw Data'!B59 -> 5000 | C10: ='Raw Data'!C59 -> 4828 | D10: =C10-('IS (real)'!E3*Assumptions!E15)-('IS (real)'!E3*Assumptions!E14) -> 4798.0026 | E10: =D10-('IS (real)'!F3*Assumptions!F15)-('IS (real)'!F3*Assumptions!F14) -> 4767.8762 | F10: =E10-('IS (real)'!G3*Assumptions!G15)-('IS (real)'!G3*Assumptions!G14) -> 4736.6954 | G10: =F10-('IS (real)'!H3*Assumptions!H15)-('IS (real)'!H3*Assumptions!H14) -> 4704.0803 | H10: =G10-('IS (real)'!I3*Assumptions!I15)-('IS (real)'!I3*Assumptions!I14) -> 4669.9649
A11: Operating Lease Right-of-Use Assets | B11: ='Raw Data'!B60 -> 2718 | C11: ='Raw Data'!C60 -> 2712 | D11: =$C$11 -> 2712 | E11: =$C$11 -> 2712 | F11: =$C$11 -> 2712 | G11: =$C$11 -> 2712 | H11: =$C$11 -> 2712
A12: Intangible Assets, net | B12: ='Raw Data'!B61 -> 259 | C12: ='Raw Data'!C61 -> 259 | D12: =$C$12 -> 259 | E12: =$C$12 -> 259 | F12: =$C$12 -> 259 | G12: =$C$12 -> 259 | H12: =$C$12 -> 259
A13: Goodwill | B13: ='Raw Data'!B62 -> 240 | C13: ='Raw Data'!C62 -> 240 | D13: =$C$13 -> 240 | E13: =$C$13 -> 240 | F13: =$C$13 -> 240 | G13: =$C$13 -> 240 | H13: =$C$13 -> 240
A14: Deferred Income Taxes & Other | B14: ='Raw Data'!B63 -> 4511 | C14: ='Raw Data'!C63 -> 5178 | D14: =$C$14 -> 5178 | E14: =$C$14 -> 5178 | F14: =$C$14 -> 5178 | G14: =$C$14 -> 5178 | H14: =$C$14 -> 5178
A15: Total Assets | B15: =SUM(B9:B14) -> 38110 | C15: =SUM(C9:C14) -> 36579 | D15: =SUM(D9:D14) -> 38286.272 | E15: =SUM(E9:E14) -> 40480.771 | F15: =SUM(F9:F14) -> 42912.144 | G15: =SUM(G9:G14) -> 45577.174 | H15: =SUM(H9:H14) -> 48453.221
A16: LIABILITIES
A17: Current Portion of Long-Term Debt | B17: ='Raw Data'!B65 -> 1000 | C17: ='Raw Data'!C65 -> — | D17: =C17 -> — | E17: =D17 -> — | F17: =E17 -> — | G17: =F17 -> — | H17: =G17 -> —
A18: Notes Payable | B18: ='Raw Data'!B66 -> 6 | C18: ='Raw Data'!C66 -> 5 | D18: =$C$18 -> 5 | E18: =$C$18 -> 5 | F18: =$C$18 -> 5 | G18: =$C$18 -> 5 | H18: =$C$18 -> 5
A19: Accounts Payable | B19: ='Raw Data'!B67 -> 2851 | C19: ='Raw Data'!C67 -> 3479 | D19: ='IS (real)'!E3*Assumptions!E19 -> 3022.3393 | E19: ='IS (real)'!F3*Assumptions!F19 -> 3035.3354 | F19: ='IS (real)'!G3*Assumptions!G19 -> 3141.5721 | G19: ='IS (real)'!H3*Assumptions!H19 -> 3286.0844 | H19: ='IS (real)'!I3*Assumptions!I19 -> 3437.2443
A20: Current Portion of Operating Lease Liabilities | B20: ='Raw Data'!B68 -> 477 | C20: ='Raw Data'!C68 -> 502 | D20: =$C$20 -> 502 | E20: =$C$20 -> 502 | F20: =$C$20 -> 502 | G20: =$C$20 -> 502 | H20: =$C$20 -> 502
A21: Accrued Liabilities | B21: ='Raw Data'!B69 -> 5725 | C21: ='Raw Data'!C69 -> 5911 | D21: =$C$21 -> 5911 | E21: =$C$21 -> 5911 | F21: =$C$21 -> 5911 | G21: =$C$21 -> 5911 | H21: =$C$21 -> 5911
A22: Income Taxes Payable | B22: ='Raw Data'!B70 -> 534 | C22: ='Raw Data'!C70 -> 669 | D22: =C22 -> 669 | E22: =D22 -> 669 | F22: =E22 -> 669 | G22: =F22 -> 669 | H22: =G22 -> 669
A23: Total Current Liabilities | B23: =SUM(B17:B22) -> 10593 | C23: =SUM(C17:C22) -> 10566 | D23: =SUM(D17:D22) -> 10109.339 | E23: =SUM(E17:E22) -> 10122.335 | F23: =SUM(F17:F22) -> 10228.572 | G23: =SUM(G17:G22) -> 10373.084 | H23: =SUM(H17:H22) -> 10524.244
A24: Long-Term Debt | B24: ='Raw Data'!B72 -> 7903 | C24: ='Raw Data'!C72 -> 7961 | D24: =$C$24 -> 7961 | E24: =$C$24 -> 7961 | F24: =$C$24 -> 7961 | G24: =$C$24 -> 7961 | H24: =$C$24 -> 7961
A25: Operating Lease Liabilities | B25: ='Raw Data'!B73 -> 2566 | C25: ='Raw Data'!C73 -> 2550 | D25: =$C$25 -> 2550 | E25: =$C$25 -> 2550 | F25: =$C$25 -> 2550 | G25: =$C$25 -> 2550 | H25: =$C$25 -> 2550
A26: Deferred Income Taxes & Other | B26: ='Raw Data'!B74 -> 2618 | C26: ='Raw Data'!C74 -> 2289 | D26: =$C$26 -> 2289 | E26: =$C$26 -> 2289 | F26: =$C$26 -> 2289 | G26: =$C$26 -> 2289 | H26: =$C$26 -> 2289
A27: Total Liabilities | B27: =SUM(B23:B26) -> 23680 | C27: =SUM(C23:C26) -> 23366 | D27: =SUM(D23:D26) -> 22909.339 | E27: =SUM(E23:E26) -> 22922.335 | F27: =SUM(F23:F26) -> 23028.572 | G27: =SUM(G23:G26) -> 23173.084 | H27: =SUM(H23:H26) -> 23324.244
A28: EQUITY
A29: Common Stock | B29: ='Raw Data'!B77 -> 3 | C29: ='Raw Data'!C77 -> 3 | D29: =$C$29 -> 3 | E29: =$C$29 -> 3 | F29: =$C$29 -> 3 | G29: =$C$29 -> 3 | H29: =$C$29 -> 3
A30: Capital in Excess of States Value | B30: ='Raw Data'!B78 -> 13409 | C30: ='Raw Data'!C78 -> 14195 | D30: =$C$30 -> 14195 | E30: =$C$30 -> 14195 | F30: =$C$30 -> 14195 | G30: =$C$30 -> 14195 | H30: =$C$30 -> 14195
A31: Accumulated Other Comprehensive Income (Loss) | B31: ='Raw Data'!B79 -> 53 | C31: ='Raw Data'!C79 -> -258 | D31: =$C$31 -> -258 | E31: =$C$31 -> -258 | F31: =$C$31 -> -258 | G31: =$C$31 -> -258 | H31: =$C$31 -> -258
A32: Retained Earnings (Deficit) | B32: ='Raw Data'!B80 -> 965 | C32: ='Raw Data'!C80 -> -727 | D32: =C32+'IS (real)'!E14 +'CFS (real)'!E27 -> 1436.9324 | E32: =D32+'IS (real)'!F14 +'CFS (real)'!F27 -> 3618.4355 | F32: =E32+'IS (real)'!G14 +'CFS (real)'!G27 -> 5943.5716 | G32: =F32+'IS (real)'!H14 +'CFS (real)'!H27 -> 8464.0893 | H32: =G32+'IS (real)'!I14 +'CFS (real)'!I27 -> 11188.976
A33: Total Shareholders Equity | B33: =SUM(B29:B32) -> 14430 | C33: =SUM(C29:C32) -> 13213 | D33: =SUM(D29:D32) -> 15376.932 | E33: =SUM(E29:E32) -> 17558.436 | F33: =SUM(F29:F32) -> 19883.572 | G33: =SUM(G29:G32) -> 22404.089 | H33: =SUM(H29:H32) -> 25128.976
A34: Total Liabilities & Equity | B34: =B33+B27 -> 38110 | C34: =C33+C27 -> 36579 | D34: =D33+D27 -> 38286.272 | E34: =E33+E27 -> 40480.771 | F34: =F33+F27 -> 42912.144 | G34: =G33+G27 -> 45577.174 | H34: =H33+H27 -> 48453.221
A36: Balance Check | B36: =B15-B34 -> 0 | C36: =C15-C34 -> 0 | D36: =D15-D34 -> 0 | E36: =E15-E34 -> 0 | F36: =F15-F34 -> 0 | G36: =G15-G34 -> 0 | H36: =H15-H34 -> 0
C44: STI | D44: =D34-(D15-D5) -> 3841.1667 | E44: =E34-(E15-E5) -> 5919.8333 | F44: =F34-(F15-F5) -> 7998.5 | G44: =G34-(G15-G5) -> 10077.167 | H44: =H34-(H15-H5) -> 12155.833

Sheet CFS (real)
A2: Cash Flow Statement | B2: 2023A | C2: 2024A | D2: 2025A | E2: 2026E | F2: 2027E | G2: 2028E | H2: 2029E | I2: 2030E
A3: OPERATING ACTIVITIES
A4: Net Income | B4: ='IS (real)'!B14 -> 5070 | C4: ='IS (real)'!C14 -> 5700 | D4: ='IS (real)'!D14 -> 3219 | E4: ='IS (real)'!E14 -> 4324.2657 | F4: ='IS (real)'!F14 -> 4341.8365 | G4: ='IS (real)'!G14 -> 4485.4693 | H4: ='IS (real)'!H14 -> 4680.8511 | I4: ='IS (real)'!I14 -> 4885.2204
A5: D&A | B5: ='Raw Data'!B23 -> 703 | C5: ='Raw Data'!C23 -> 796 | D5: ='Raw Data'!D23 -> 775 | E5: ='IS (real)'!E3*Assumptions!E14 -> 708.87333 | F5: ='IS (real)'!F3*Assumptions!F14 -> 711.92149 | G5: ='IS (real)'!G3*Assumptions!G14 -> 736.83874 | H5: ='IS (real)'!H3*Assumptions!H14 -> 770.73332 | I5: ='IS (real)'!I3*Assumptions!I14 -> 806.18705
A6: Deferred Income Taxes | B6: ='Raw Data'!B24 -> -117 | C6: ='Raw Data'!C24 -> -497 | D6: ='Raw Data'!D24 -> -288 | E6: =$D$6 -> -288 | F6: =$D$6 -> -288 | G6: =$D$6 -> -288 | H6: =$D$6 -> -288 | I6: =$D$6 -> -288
A7: Stock-Based Compensation | B7: ='Raw Data'!B25 -> 755 | C7: ='Raw Data'!C25 -> 804 | D7: ='Raw Data'!D25 -> 709 | E7: =AVERAGE($B$7:$D$7) -> 756 | F7: =AVERAGE($B$7:$D$7) -> 756 | G7: =AVERAGE($B$7:$D$7) -> 756 | H7: =AVERAGE($B$7:$D$7) -> 756 | I7: =AVERAGE($B$7:$D$7) -> 756
A8: Impairment and Other | B8: ='Raw Data'!B26 -> 156 | C8: ='Raw Data'!C26 -> 48 | D8: ='Raw Data'!D26 -> 33 | E8: — | F8: — | G8: — | H8: — | I8: —
A9: Net Foreign Currency Adjustments | B9: ='Raw Data'!B27 -> -213 | C9: ='Raw Data'!C27 -> -138 | D9: ='Raw Data'!D27 -> 37 | E9: — | F9: — | G9: — | H9: — | I9: —
A10: Change in AR | B10: ='Raw Data'!B28 -> 489 | C10: ='Raw Data'!C28 -> -329 | D10: ='Raw Data'!D28 -> -257 | E10: ='BS (real)'!C6-'BS (real)'!D6 -> 592.44611 | F10: ='BS (real)'!D6-'BS (real)'!E6 -> -17.735582 | G10: ='BS (real)'!E6-'BS (real)'!F6 -> -144.98013 | H10: ='BS (real)'!F6-'BS (real)'!G6 -> -197.2144 | I10: ='BS (real)'!G6-'BS (real)'!H6 -> -206.28626
A11: Change in Inventories | B11: ='Raw Data'!B29 -> -133 | C11: ='Raw Data'!C29 -> 908 | D11: ='Raw Data'!D29 -> 120 | E11: ='BS (real)'!C7-'BS (real)'!D7 -> 719.06836 | F11: ='BS (real)'!D7-'BS (real)'!E7 -> -29.110706 | G11: ='BS (real)'!E7-'BS (real)'!F7 -> -237.96648 | H11: ='BS (real)'!F7-'BS (real)'!G7 -> -323.70241 | I11: ='BS (real)'!G7-'BS (real)'!H7 -> -338.59272
A12: Change in Prepaid/Other | B12: ='Raw Data'!B30 -> -644 | C12: ='Raw Data'!C30 -> -260 | D12: ='Raw Data'!D30 -> -224 | E12: =$D$12 -> -224 | F12: =$D$12 -> -224 | G12: =$D$12 -> -224 | H12: =$D$12 -> -224 | I12: =$D$12 -> -224
A13: Change in AP/Accrued Liabilities | B13: ='Raw Data'!B31 -> -225 | C13: ='Raw Data'!C31 -> 397 | D13: ='Raw Data'!D31 -> -426 | E13: ='BS (real)'!D19-'BS (real)'!C19 -> -456.66068 | F13: ='BS (real)'!E19-'BS (real)'!D19 -> 12.996059 | G13: ='BS (real)'!F19-'BS (real)'!E19 -> 106.23674 | H13: ='BS (real)'!G19-'BS (real)'!F19 -> 144.51232 | I13: ='BS (real)'!H19-'BS (real)'!G19 -> 151.15988
A14: Cash from Operations | B14: =SUM(B4:B13) -> 5841 | C14: =SUM(C4:C13) -> 7429 | D14: =SUM(D4:D13) -> 3698 | E14: =SUM(E4:E13) -> 6131.9928 | F14: =SUM(F4:F13) -> 5263.9077 | G14: =SUM(G4:G13) -> 5189.5982 | H14: =SUM(H4:H13) -> 5319.1799 | I14: =SUM(I4:I13) -> 5541.6883
A15: INVESTING ACTIVITIES
A16: Purchases of Short-Term Investments | B16: ='Raw Data'!B33 -> -6059 | C16: ='Raw Data'!C33 -> -4767 | D16: ='Raw Data'!D33 -> -3234 | E16: =$D16 -> -3234 | F16: =$D16 -> -3234 | G16: =$D16 -> -3234 | H16: =$D16 -> -3234 | I16: =$D16 -> -3234
A17: Maturities of Short-Term Investments | B17: ='Raw Data'!B34 -> 3356 | C17: ='Raw Data'!C34 -> 2269 | D17: ='Raw Data'!D34 -> 319 | E17: =$D17 -> 319 | F17: =$D17 -> 319 | G17: =$D17 -> 319 | H17: =$D17 -> 319 | I17: =$D17 -> 319
A18: Sales of Short-Term Investments | B18: ='Raw Data'!B35 -> 4184 | C18: ='Raw Data'!C35 -> 4219 | D18: ='Raw Data'!D35 -> 3062 | E18: =$D18 -> 3062 | F18: =$D18 -> 3062 | G18: =$D18 -> 3062 | H18: =$D18 -> 3062 | I18: =$D18 -> 3062
A19: Capex | B19: ='Raw Data'!B36 -> -969 | C19: ='Raw Data'!C36 -> -812 | D19: ='Raw Data'!D36 -> -430 | E19: ='IS (real)'!E3*Assumptions!E15 -> -678.87594 | F19: ='IS (real)'!F3*Assumptions!F15 -> -681.79511 | G19: ='IS (real)'!G3*Assumptions!G15 -> -705.65794 | H19: ='IS (real)'!H3*Assumptions!H15 -> -738.1182 | I19: ='IS (real)'!I3*Assumptions!I15 -> -772.07164
A20: Other Investing | B20: ='Raw Data'!B37 -> 52 | C20: ='Raw Data'!C37 -> -15 | D20: ='Raw Data'!D37 -> 8 | E20: =$C$23 -> — | F20: =$C$23 -> — | G20: =$C$23 -> — | H20: =$C$23 -> — | I20: =$C$23 -> —
A21: Cash from Investing | B21: =SUM(B16:B20) -> 564 | C21: =SUM(C16:C20) -> 894 | D21: =SUM(D16:D20) -> -275 | E21: =SUM(E16:E20) -> -531.87594 | F21: =SUM(F16:F20) -> -534.79511 | G21: =SUM(G16:G20) -> -558.65794 | H21: =SUM(H16:H20) -> -591.1182 | I21: =SUM(I16:I20) -> -625.07164
A22: FINANCING ACTIVITIES
A23: Increase in Notes Payable | B23: ='Raw Data'!B39 -> -4 | C23: ='Raw Data'!C39 -> — | D23: ='Raw Data'!D39 -> -1 | E23: — | F23: — | G23: — | H23: — | I23: —
A24: Repayment of Borrowings | B24: ='Raw Data'!B40 -> -500 | C24: ='Raw Data'!C40 -> — | D24: ='Raw Data'!D40 -> -1000 | E24: — | F24: — | G24: — | H24: — | I24: —
A25: Stock Option Proceeds | B25: ='Raw Data'!B41 -> 651 | C25: ='Raw Data'!C41 -> 667 | D25: ='Raw Data'!D41 -> 551 | E25: =AVERAGE($B25:$D25) -> 623 | F25: =AVERAGE($B25:$D25) -> 623 | G25: =AVERAGE($B25:$D25) -> 623 | H25: =AVERAGE($B25:$D25) -> 623 | I25: =AVERAGE($B25:$D25) -> 623
A26: Share Repurchases | B26: ='Raw Data'!B42 -> -5480 | C26: ='Raw Data'!C42 -> -4250 | D26: ='Raw Data'!D42 -> -2985 | E26: =$D$26 -> -2985 | F26: =$D$26 -> -2985 | G26: =$D$26 -> -2985 | H26: =$D$26 -> -2985 | I26: =$D$26 -> -2985
A27: Dividends | B27: ='Raw Data'!B43 -> -2012 | C27: ='Raw Data'!C43 -> -2169 | D27: ='Raw Data'!D43 -> -2300 | E27: =AVERAGE($B27:$D27) -> -2160.3333 | F27: =AVERAGE($B27:$D27) -> -2160.3333 | G27: =AVERAGE($B27:$D27) -> -2160.3333 | H27: =AVERAGE($B27:$D27) -> -2160.3333 | I27: =AVERAGE($B27:$D27) -> -2160.3333
A28: Other Financing | B28: ='Raw Data'!B44 -> -102 | C28: ='Raw Data'!C44 -> -136 | D28: ='Raw Data'!D44 -> -85 | E28: =AVERAGE($B28:$D28) -> -107.66667 | F28: =AVERAGE($B28:$D28) -> -107.66667 | G28: =AVERAGE($B28:$D28) -> -107.66667 | H28: =AVERAGE($B28:$D28) -> -107.66667 | I28: =AVERAGE($B28:$D28) -> -107.66667
A29: Cash From Financing | B29: =SUM(B23:B28) -> -7447 | C29: =SUM(C23:C28) -> -5888 | D29: =SUM(D23:D28) -> -5820 | E29: =SUM(E23:E28) -> -4630 | F29: =SUM(F23:F28) -> -4630 | G29: =SUM(G23:G28) -> -4630 | H29: =SUM(H23:H28) -> -4630 | I29: =SUM(I23:I28) -> -4630
A30: RECONCILIATION
A31: FX Effect on Cash | B31: ='Raw Data'!B46 -> -91 | C31: ='Raw Data'!C46 -> -16 | D31: ='Raw Data'!D46 -> 1 | E31: =0 -> 0 | F31: =0 -> 0 | G31: =0 -> 0 | H31: =0 -> 0 | I31: =0 -> 0
A32: Net Change in Cash | B32: =B31+B29+B21+B14 -> -1133 | C32: =C31+C29+C21+C14 -> 2419 | D32: =D31+D29+D21+D14 -> -2396 | E32: =E31+E29+E21+E14 -> 970.1169 | F32: =F31+F29+F21+F14 -> 99.112634 | G32: =G31+G29+G21+G14 -> 0.94027186 | H32: =H31+H29+H21+H14 -> 98.061703 | I32: =I31+I29+I21+I14 -> 286.61668
A33: Beginning Cash | B33: ='Raw Data'!B48 -> 8574 | C33: =B34 -> 7441 | D33: =C34 -> 9860 | E33: =D34 -> 7464 | F33: =E34 -> 8434.1169 | G33: =F34 -> 8533.2295 | H33: =G34 -> 8534.1698 | I33: =H34 -> 8632.2315
A34: Ending Cash | B34: =B33+B32 -> 7441 | C34: =C33+C32 -> 9860 | D34: =D33+D32 -> 7464 | E34: =E33+E32 -> 8434.1169 | F34: =F33+F32 -> 8533.2295 | G34: =G33+G32 -> 8534.1698 | H34: =H33+H32 -> 8632.2315 | I34: =I33+I32 -> 8918.8482

Sheet Assumptions
A2: Assumptions | B2: 2023A | C2: 2024A | D2: 2025A | E2: 2026E | F2: 2027E | G2: 2028E | H2: 2029E | I2: 2030E
A3: GROWTH
A4: Revenue Growth Rate % | C4: =('IS (real)'!C3/'IS (real)'!B3)-1 -> 0.0028310912 | D4: =('IS (real)'!D3/'IS (real)'!C3)-1 -> -0.098380125 | E4: -0.0008 | F4: 0.0043 | G4: 0.035 | H4: 0.046 | I4: 0.046
A5: MARGINS
A6: Gross Margin % | B6: ='IS (real)'!B5/'IS (real)'!B3 -> 0.43524611 | C6: ='IS (real)'!C5/'IS (real)'!C3 -> 0.44560181 | D6: ='IS (real)'!D5/'IS (real)'!D3 -> 0.42734674 | E6: =AVERAGE($B$6:$D$6) -> 0.43606488 | F6: =AVERAGE($B$6:$D$6) -> 0.43606488 | G6: =AVERAGE($B$6:$D$6) -> 0.43606488 | H6: =AVERAGE($B$6:$D$6) -> 0.43606488 | I6: =AVERAGE($B$6:$D$6) -> 0.43606488
A7: EBIT Margin % | B7: ='IS (real)'!B9/'IS (real)'!B3 -> 0.115489 | C7: ='IS (real)'!C9/'IS (real)'!C3 -> 0.12287294 | D7: ='IS (real)'!D9/'IS (real)'!D3 -> 0.079941264
A8: Net Margin % | B8: ='IS (real)'!B14/'IS (real)'!B3 -> 0.09899057 | C8: ='IS (real)'!C14/'IS (real)'!C3 -> 0.11097699 | D8: ='IS (real)'!D14/'IS (real)'!D3 -> 0.069511326
A9: COST DRIVERS
A10: Demand Creation as % of Revenue | B10: ='IS (real)'!B6/'IS (real)'!B3 -> 0.079270555 | C10: ='IS (real)'!C6/'IS (real)'!C3 -> 0.083427437 | D10: ='IS (real)'!D6/'IS (real)'!D3 -> 0.10125462 | E10: =AVERAGE($B$10:$D$10) -> 0.087984202 | F10: =AVERAGE($B$10:$D$10) -> 0.087984202 | G10: =AVERAGE($B$10:$D$10) -> 0.087984202 | H10: =AVERAGE($B$10:$D$10) -> 0.087984202 | I10: =AVERAGE($B$10:$D$10) -> 0.087984202
A11: Operating Overhead as % of Revenue | B11: ='IS (real)'!B7/'IS (real)'!B3 -> 0.24048656 | C11: ='IS (real)'!C7/'IS (real)'!C3 -> 0.23930143 | D11: ='IS (real)'!D7/'IS (real)'!D3 -> 0.24615086 | E11: =AVERAGE($B11:$D11) -> 0.24197961 | F11: =AVERAGE($B11:$D11) -> 0.24197961 | G11: =AVERAGE($B11:$D11) -> 0.24197961 | H11: =AVERAGE($B11:$D11) -> 0.24197961 | I11: =AVERAGE($B11:$D11) -> 0.24197961
A12: Effective Tax Rate % | B12: ='IS (real)'!B13/'IS (real)'!B12 -> 0.18238994 | C12: ='IS (real)'!C13/'IS (real)'!C12 -> 0.14925373 | D12: ='IS (real)'!D13/'IS (real)'!D12 -> 0.17142857 | E12: =AVERAGE($B12:$D12) -> 0.16769075 | F12: =AVERAGE($B12:$D12) -> 0.16769075 | G12: =AVERAGE($B12:$D12) -> 0.16769075 | H12: =AVERAGE($B12:$D12) -> 0.16769075 | I12: =AVERAGE($B12:$D12) -> 0.16769075
A13: CASH FLOW DRIVERS
A14: D&A as % of Revenue | B14: ='IS (real)'!B16/'IS (real)'!B3 -> 0.013725911 | C14: ='IS (real)'!C16/'IS (real)'!C3 -> 0.015497839 | D14: ='IS (real)'!D16/'IS (real)'!D3 -> 0.016735408 | E14: =AVERAGE($B14:$D14) -> 0.015319719 | F14: =AVERAGE($B14:$D14) -> 0.015319719 | G14: =AVERAGE($B14:$D14) -> 0.015319719 | H14: =AVERAGE($B14:$D14) -> 0.015319719 | I14: =AVERAGE($B14:$D14) -> 0.015319719
A15: Capex as % of Revenue | B15: ='CFS (real)'!B19/'IS (real)'!B3 -> -0.018919499 | C15: ='CFS (real)'!C19/'IS (real)'!C3 -> -0.015809353 | D15: ='CFS (real)'!D19/'IS (real)'!D3 -> -0.0092854521 | E15: =AVERAGE($B15:$D15) -> -0.014671435 | F15: =AVERAGE($B15:$D15) -> -0.014671435 | G15: =AVERAGE($B15:$D15) -> -0.014671435 | H15: =AVERAGE($B15:$D15) -> -0.014671435 | I15: =AVERAGE($B15:$D15) -> -0.014671435
A16: BALANCE SHEET DRIVERS
A17: Accounts Receivable as % of Revenue | C17: ='BS (real)'!B6/'IS (real)'!B3 -> 0.086436144 | D17: ='BS (real)'!C6/'IS (real)'!C3 -> 0.091838324 | E17: =AVERAGE($C17:$D17) -> 0.089137234 | F17: =AVERAGE($C17:$D17) -> 0.089137234 | G17: =AVERAGE($C17:$D17) -> 0.089137234 | H17: =AVERAGE($C17:$D17) -> 0.089137234 | I17: =AVERAGE($C17:$D17) -> 0.089137234
A18: Inventories as % of Revenue | C18: ='BS (real)'!B7/'IS (real)'!B3 -> 0.14680672 | D18: ='BS (real)'!C7/'IS (real)'!C3 -> 0.14580819 | E18: =AVERAGE($C18:$D18) -> 0.14630745 | F18: =AVERAGE($C18:$D18) -> 0.14630745 | G18: =AVERAGE($C18:$D18) -> 0.14630745 | H18: =AVERAGE($C18:$D18) -> 0.14630745 | I18: =AVERAGE($C18:$D18) -> 0.14630745
A19: Accounts Payable as % of Revenue | C19: ='BS (real)'!B19/'IS (real)'!C3 -> 0.055507963 | D19: ='BS (real)'!C19/'IS (real)'!D3 -> 0.075125785 | E19: =AVERAGE($C19:$D19) -> 0.065316874 | F19: =AVERAGE($C19:$D19) -> 0.065316874 | G19: =AVERAGE($C19:$D19) -> 0.065316874 | H19: =AVERAGE($C19:$D19) -> 0.065316874 | I19: =AVERAGE($C19:$D19) -> 0.065316874

Sheet Sources
B2: Source Name | C2: URL
B3: Yahoo Finance Analyst Consensus | C3: https://ca.finance.yahoo.com/quote/NKE/analysis/
B4: Finbox | C4: https://finbox.com/NYSE:NKE/explorer/revenue_proj_growth/
B5: SEC EDGAR Nike 10k FY2025 | C5: sec.gov/edgar
B6: Nike Q4 FY2025 Earnings Call Transcript | C6: https://seekingalpha.com/news/4571029-nike-anticipates-q4-revenue-down-2-percent-to-4-percent-as-it-targets-finishing-win-now
